Workbook

Sheet Útmutató
A1: Termék-ellenőrző táblázat – Quadris weboldal
A3: Mit mutat?
A4: A „Termékek” lapon a jelenleg KÉP NÉLKÜLI termékek vannak, soronként egy: van-e műszaki adata, honnan jött az adat, hol kerestük és hol nem találtuk.
A5: A „Beszállítók” lap beszállítónként összesíti a kép nélküli termékeket (képletekkel, a jelölések után is frissül).
A7: Mit kell kitölteni? (sárga oszlopok a „Termékek” lapon)
A8: C – TÖRÖLHETŐ: legördülőből „IGEN”, ha a terméket le lehet venni a weboldalról és mindenhonnan (katalógus, kereső, ajánlatkérő).
A9: D – Megjegyzés (Quadris): bármi, amit tudnunk kell – pl. „kép: a beszállító új katalógusában a 34. oldalon”, „helyes cikkszám: 7318”, „nem forgalmazzuk”.
A10: Példa: C = IGEN, D = „Kifutott termék, nem rendelhető.”
A11: A többi oszlopot kérjük, ne módosítsák – az S oszlop (azonosító) alapján olvassuk vissza a fájlt.
A13: Oszlopok jelentése
A14: Kép (db) / Műszaki adat (db): a weboldalon megjelenő képek és adatsorok száma.
A15: Állapot: Rendben / Nincs kép / Nincs adat / Nincs kép és adat (képlet a két számból).
... A22: Forrás: a weboldal adatai (src/data/catalog.json, termekadatok.json, bovitett.json) – generálva: scripts/termekadatok/ellenorzo_excel.py

Sheet Beszállítók
A1: Beszállító | B1: Kép nélküli termékek | C1: Ebből műszaki adat sincs | D1: Ebből van műszaki adat | E1: Kerestük? | F1: Hol kerestük | G1: Törlésre jelölve
A2: (nincs megadva) | B2: =COUNTIF(Termékek!$A$2:$A$288,A2) | C2: =COUNTIFS(Termékek!$A$2:$A$288,A2,Termékek!$M$2:$M$288,"Nincs kép és adat") | D2: =B2-C2 | E2: Nem | F2: Quadris-megnevezés (nincs beszállítói forrás) | G2: =COUNTIFS(Termékek!$A$2:$A$288,A2,Termékek!$C$2:$C$288,"IGEN")
A3: AC-RIU | B3: =COUNTIF(Termékek!$A$2:$A$288,A3) | C3: =COUNTIFS(Termékek!$A$2:$A$288,A3,Termékek!$M$2:$M$288,"Nincs kép és adat") | D3: =B3-C3 | E3: Nem | F3: – | G3: =COUNTIFS(Termékek!$A$2:$A$288,A3,Termékek!$C$2:$C$288,"IGEN")
A4: Allco | B4: =COUNTIF(Termékek!$A$2:$A$288,A4) | C4: =COUNTIFS(Termékek!$A$2:$A$288,A4,Termékek!$M$2:$M$288,"Nincs kép és adat") | D4: =B4-C4 | E4: Nem | F4: – | G4: =COUNTIFS(Termékek!$A$2:$A$288,A4,Termékek!$C$2:$C$288,"IGEN")
A5: ALSAP | B5: =COUNTIF(Termékek!$A$2:$A$288,A5) | C5: =COUNTIFS(Termékek!$A$2:$A$288,A5,Termékek!$M$2:$M$288,"Nincs kép és adat") | D5: =B5-C5 | E5: Nem | F5: – | G5: =COUNTIFS(Termékek!$A$2:$A$288,A5,Termékek!$C$2:$C$288,"IGEN")
A6: Alu-SV | B6: =COUNTIF(Termékek!$A$2:$A$288,A6) | C6: =COUNTIFS(Termékek!$A$2:$A$288,A6,Termékek!$M$2:$M$288,"Nincs kép és adat") | D6: =B6-C6 | E6: Igen | F6: alu-sv.com webáruház, keresés rendelési számra | G6: =COUNTIFS(Termékek!$A$2:$A$288,A6,Termékek!$C$2:$C$288,"IGEN")
A7: BODEGA | B7: =COUNTIF(Termékek!$A$2:$A$288,A7) | C7: =COUNTIFS(Termékek!$A$2:$A$288,A7,Termékek!$M$2:$M$288,"Nincs kép és adat") | D7: =B7-C7 | E7: Igen | F7: Bodega Bordwände katalógus 2010 (PDF); bodega.it oldaltérkép | G7: =COUNTIFS(Termékek!$A$2:$A$288,A7,Termékek!$C$2:$C$288,"IGEN")
A8: Car-Alu | B8: =COUNTIF(Termékek!$A$2:$A$288,A8) | C8: =COUNTIFS(Termékek!$A$2:$A$288,A8,Termékek!$M$2:$M$288,"Nincs kép és adat") | D8: =B8-C8 | E8: Igen | F8: caralushop.nl webshop | G8: =COUNTIFS(Termékek!$A$2:$A$288,A8,Termékek!$C$2:$C$288,"IGEN")
A9: Cargoframes Czech | B9: =COUNTIF(Termékek!$A$2:$A$288,A9) | C9: =COUNTIFS(Termékek!$A$2:$A$288,A9,Termékek!$M$2:$M$288,"Nincs kép és adat") | D9: =B9-C9 | E9: Igen | F9: cargoframes.eu oldaltérkép; Cargo Frames profilrajzok és műszaki lista (Quadris e-mail) | G9: =COUNTIFS(Termékek!$A$2:$A$288,A9,Termékek!$C$2:$C$288,"IGEN")
A10: Cimaplast | B10: =COUNTIF(Termékek!$A$2:$A$288,A10) | C10: =COUNTIFS(Termékek!$A$2:$A$288,A10,Termékek!$M$2:$M$288,"Nincs kép és adat") | D10: =B10-C10 | E10: Igen | F10: cimaplast.it kategóriaoldalak | G10: =COUNTIFS(Termékek!$A$2:$A$288,A10,Termékek!$C$2:$C$288,"IGEN")
A11: CNT conta | B11: =COUNTIF(Termékek!$A$2:$A$288,A11) | C11: =COUNTIFS(Termékek!$A$2:$A$288,A11,Termékek!$M$2:$M$288,"Nincs kép és adat") | D11: =B11-C11 | E11: Nem | F11: – | G11: =COUNTIFS(Termékek!$A$2:$A$288,A11,Termékek!$C$2:$C$288,"IGEN")
A12: Constellium Decin | B12: =COUNTIF(Termékek!$A$2:$A$288,A12) | C12: =COUNTIFS(Termékek!$A$2:$A$288,A12,Termékek!$M$2:$M$288,"Nincs kép és adat") | D12: =B12-C12 | E12: Igen | F12: alu-sv.com (a kód utolsó számjegyei); Ital Accessori katalógus; Drive: CONSTELLIUM DECIN Excel – nem letölthető (>10 MB) | G12: =COUNTIFS(Termékek!$A$2:$A$288,A12,Termékek!$C$2:$C$288,"IGEN")
A13: D.LaPorte | B13: =COUNTIF(Termékek!$A$2:$A$288,A13) | C13: =COUNTIFS(Termékek!$A$2:$A$288,A13,Termékek!$M$2:$M$288,"Nincs kép és adat") | D13: =B13-C13 | E13: Nem | F13: – | G13: =COUNTIFS(Termékek!$A$2:$A$288,A13,Termékek!$C$2:$C$288,"IGEN")
... A43: Westfalia | B43: =COUNTIF(Termékek!$A$2:$A$288,A43) | C43: =COUNTIFS(Termékek!$A$2:$A$288,A43,Termékek!$M$2:$M$288,"Nincs kép és adat") | D43: =B43-C43 | E43: Nem | F43: – | G43: =COUNTIFS(Termékek!$A$2:$A$288,A43,Termékek!$C$2:$C$288,"IGEN")
A44: Összesen | B44: =SUM(B2:B43) | C44: =SUM(C2:C43) | D44: =SUM(D2:D43) | G44: =SUM(G2:G43)

Sheet Termékek
A1: Beszállító | B1: Megnevezés | C1: TÖRÖLHETŐ | D1: Megjegyzés (Quadris) | E1: Quadris cikkszám | F1: Beszállítói kód | G1: Termékcsoport | H1: Kategória | I1: Eredet | J1: Kép (db) | K1: Műszaki adat (db) | L1: Leírás | M1: Állapot | N1: Kerestük? | O1: Hol kerestük | P1: Eredmény / hol nem találtuk | Q1: Adatforrás | R1: Weboldal | S1: Azonosító (slug)
A2: (nincs megadva) | B2: Bill. Rakonca 500 mm első J-B | E2: 351704 | G2: Billencs alkatrészek | H2: Billencs rakoncák | I2: Quadris Excel | J2: 0 | K2: 0 | L2: nincs | M2: =IF(AND(J2>0,K2>0),"Rendben",IF(AND(J2=0,K2=0),"Nincs kép és adat",IF(J2=0,"Nincs kép","Nincs adat"))) | N2: Nem | O2: Quadris-megnevezés (nincs beszállítói forrás) | P2: Nem kerestük – nincs ismert weboldal vagy katalógus | R2: https://website-9ib.pages.dev/termek/351704-bill-rakonca-500-mm-elso-j-b/ | S2: 351704-bill-rakonca-500-mm-elso-j-b
A3: (nincs megadva) | B3: Bill. Rakonca 500 mm hátsó J-B | E3: 351707 | G3: Billencs alkatrészek | H3: Billencs rakoncák | I3: Quadris Excel | J3: 0 | K3: 0 | L3: nincs | M3: =IF(AND(J3>0,K3>0),"Rendben",IF(AND(J3=0,K3=0),"Nincs kép és adat",IF(J3=0,"Nincs kép","Nincs adat"))) | N3: Nem | O3: Quadris-megnevezés (nincs beszállítói forrás) | P3: Nem kerestük – nincs ismert weboldal vagy katalógus | R3: https://website-9ib.pages.dev/termek/351707-bill-rakonca-500-mm-hatso-j-b/ | S3: 351707-bill-rakonca-500-mm-hatso-j-b
A4: (nincs megadva) | B4: Bill. Rakonca 500 mm középső | E4: 351706 | G4: Billencs alkatrészek | H4: Billencs rakoncák | I4: Quadris Excel | J4: 0 | K4: 0 | L4: nincs | M4: =IF(AND(J4>0,K4>0),"Rendben",IF(AND(J4=0,K4=0),"Nincs kép és adat",IF(J4=0,"Nincs kép","Nincs adat"))) | N4: Nem | O4: Quadris-megnevezés (nincs beszállítói forrás) | P4: Nem kerestük – nincs ismert weboldal vagy katalógus | R4: https://website-9ib.pages.dev/termek/351706-bill-rakonca-500-mm-kozepso/ | S4: 351706-bill-rakonca-500-mm-kozepso
A5: (nincs megadva) | B5: Perforál acél keret 27 mm vállal L: 7500 | E5: 147443/ST | G5: Billencs alkatrészek | H5: Billencs alkatrészek | I5: Quadris Excel | J5: 0 | K5: 0 | L5: nincs | M5: =IF(AND(J5>0,K5>0),"Rendben",IF(AND(J5=0,K5=0),"Nincs kép és adat",IF(J5=0,"Nincs kép","Nincs adat"))) | N5: Nem | O5: Quadris-megnevezés (nincs beszállítói forrás) | P5: Nem kerestük – nincs ismert weboldal vagy katalógus | R5: https://website-9ib.pages.dev/termek/147443-st-perforal-acel-keret-27-mm-vallal-l-7500/ | S5: 147443-st-perforal-acel-keret-27-mm-vallal-l-7500
A6: (nincs megadva) | B6: SP.41 Billencs KÖZÉPSŐ rakonca 400/120 mm | E6: 3510206 | F6: D010206 | G6: Billencs alkatrészek | H6: Billencs rakoncák | I6: Quadris Excel | J6: 0 | K6: 0 | L6: nincs | M6: =IF(AND(J6>0,K6>0),"Rendben",IF(AND(J6=0,K6=0),"Nincs kép és adat",IF(J6=0,"Nincs kép","Nincs adat"))) | N6: Nem | O6: Quadris-megnevezés (nincs beszállítói forrás) | P6: Nem kerestük – nincs ismert weboldal vagy katalógus | R6: https://website-9ib.pages.dev/termek/3510206-sp-41-billencs-kozepso-rakonca-400-120-mm/ | S6: 3510206-sp-41-billencs-kozepso-rakonca-400-120-mm
A7: (nincs megadva) | B7: SP.41 Billencs első rakonca 400/85 mm B | E7: 3510204 | F7: D010204 | G7: Billencs alkatrészek | H7: Billencs rakoncák | I7: Quadris Excel | J7: 0 | K7: 0 | L7: nincs | M7: =IF(AND(J7>0,K7>0),"Rendben",IF(AND(J7=0,K7=0),"Nincs kép és adat",IF(J7=0,"Nincs kép","Nincs adat"))) | N7: Nem | O7: Quadris-megnevezés (nincs beszállítói forrás) | P7: Nem kerestük – nincs ismert weboldal vagy katalógus | R7: https://website-9ib.pages.dev/termek/3510204-sp-41-billencs-elso-rakonca-400-85-mm-b/ | S7: 3510204-sp-41-billencs-elso-rakonca-400-85-mm-b
A8: (nincs megadva) | B8: SP.41 Billencs első rakonca 400/85 mm J | E8: 3510204 | F8: D010204 | G8: Billencs alkatrészek | H8: Billencs rakoncák | I8: Quadris Excel | J8: 0 | K8: 0 | L8: nincs | M8: =IF(AND(J8>0,K8>0),"Rendben",IF(AND(J8=0,K8=0),"Nincs kép és adat",IF(J8=0,"Nincs kép","Nincs adat"))) | N8: Nem | O8: Quadris-megnevezés (nincs beszállítói forrás) | P8: Nem kerestük – nincs ismert weboldal vagy katalógus | R8: https://website-9ib.pages.dev/termek/3510204-sp-41-billencs-elso-rakonca-400-85-mm-j/ | S8: 3510204-sp-41-billencs-elso-rakonca-400-85-mm-j
A9: (nincs megadva) | B9: SP.41 Billencs hátsó rakonca 400/120 mm B | E9: 3510207 | F9: D010207 | G9: Billencs alkatrészek | H9: Billencs rakoncák | I9: Quadris Excel | J9: 0 | K9: 0 | L9: nincs | M9: =IF(AND(J9>0,K9>0),"Rendben",IF(AND(J9=0,K9=0),"Nincs kép és adat",IF(J9=0,"Nincs kép","Nincs adat"))) | N9: Nem | O9: Quadris-megnevezés (nincs beszállítói forrás) | P9: Nem kerestük – nincs ismert weboldal vagy katalógus | R9: https://website-9ib.pages.dev/termek/3510207-sp-41-billencs-hatso-rakonca-400-120-mm-b/ | S9: 3510207-sp-41-billencs-hatso-rakonca-400-120-mm-b
A10: (nincs megadva) | B10: SP.41 Billencs hátsó rakonca 400/120 mm J | E10: 3510207 | F10: D010207 | G10: Billencs alkatrészek | H10: Billencs rakoncák | I10: Quadris Excel | J10: 0 | K10: 0 | L10: nincs | M10: =IF(AND(J10>0,K10>0),"Rendben",IF(AND(J10=0,K10=0),"Nincs kép és adat",IF(J10=0,"Nincs kép","Nincs adat"))) | N10: Nem | O10: Quadris-megnevezés (nincs beszállítói forrás) | P10: Nem kerestük – nincs ismert weboldal vagy katalógus | R10: https://website-9ib.pages.dev/termek/3510207-sp-41-billencs-hatso-rakonca-400-120-mm-j/ | S10: 3510207-sp-41-billencs-hatso-rakonca-400-120-mm-j
A11: (nincs megadva) | B11: Hátsó ajtó alu elox | G11: Hátsó ajtók és áthajtó rámpák | H11: 2 szárnyú | I11: Quadris Excel | J11: 0 | K11: 0 | L11: nincs | M11: =IF(AND(J11>0,K11>0),"Rendben",IF(AND(J11=0,K11=0),"Nincs kép és adat",IF(J11=0,"Nincs kép","Nincs adat"))) | N11: Nem | O11: Quadris-megnevezés (nincs beszállítói forrás) | P11: Nem kerestük – nincs ismert weboldal vagy katalógus | R11: https://website-9ib.pages.dev/termek/hatso-ajto-alu-elox/ | S11: hatso-ajto-alu-elox
A12: (nincs megadva) | B12: KIT Hűtős doboz | G12: Zárt-dobozos és hűtős profilok | H12: Felépítmény készletek | I12: Quadris Excel | J12: 0 | K12: 0 | L12: nincs | M12: =IF(AND(J12>0,K12>0),"Rendben",IF(AND(J12=0,K12=0),"Nincs kép és adat",IF(J12=0,"Nincs kép","Nincs adat"))) | N12: Nem | O12: Quadris-megnevezés (nincs beszállítói forrás) | P12: Nem kerestük – nincs ismert weboldal vagy katalógus | R12: https://website-9ib.pages.dev/termek/kit-hutos-doboz/ | S12: kit-hutos-doboz
A13: (nincs megadva) | B13: Zártdobozos felépítmény készlet | G13: Zárt-dobozos és hűtős profilok | H13: Felépítmény készletek | I13: Quadris Excel | J13: 0 | K13: 0 | L13: nincs | M13: =IF(AND(J13>0,K13>0),"Rendben",IF(AND(J13=0,K13=0),"Nincs kép és adat",IF(J13=0,"Nincs kép","Nincs adat"))) | N13: Nem | O13: Quadris-megnevezés (nincs beszállítói forrás) | P13: Nem kerestük – nincs ismert weboldal vagy katalógus | R13: https://website-9ib.pages.dev/termek/zartdobozos-felepitmeny-keszlet/ | S13: zartdobozos-felepitmeny-keszlet
A14: AC-RIU | B14: Ajtóhatároló fix konzol | E14: 026801 | F14: R026801 | G14: Dobozos felépítmény alkatrészek | H14: Ajtórögzítők | I14: Quadris Excel | J14: 0 | K14: 0 | L14: nincs | M14: =IF(AND(J14>0,K14>0),"Rendben",IF(AND(J14=0,K14=0),"Nincs kép és adat",IF(J14=0,"Nincs kép","Nincs adat"))) | N14: Nem | O14: – | P14: Nem kerestük – nincs ismert weboldal vagy katalógus | R14: https://website-9ib.pages.dev/termek/026801-ajtohatarolo-fix-konzol/ | S14: 026801-ajtohatarolo-fix-konzol
A15: AC-RIU | B15: Gumis ajtóhatároló 800kg | E15: 026822 | F15: R026822 | G15: Dobozos felépítmény alkatrészek | H15: Ajtórögzítők | I15: Quadris Excel | J15: 0 | K15: 0 | L15: nincs | M15: =IF(AND(J15>0,K15>0),"Rendben",IF(AND(J15=0,K15=0),"Nincs kép és adat",IF(J15=0,"Nincs kép","Nincs adat"))) | N15: Nem | O15: – | P15: Nem kerestük – nincs ismert weboldal vagy katalógus | R15: https://website-9ib.pages.dev/termek/026822-gumis-ajtohatarolo-800kg/ | S15: 026822-gumis-ajtohatarolo-800kg
A16: AC-RIU | B16: Műanyag zártakaró | E16: 052900 | F16: 7280 005-000 | G16: Speciális felépítmény alkatrészek | H16: Egyéb | I16: Quadris Excel | J16: 0 | K16: 0 | L16: nincs | M16: =IF(AND(J16>0,K16>0),"Rendben",IF(AND(J16=0,K16=0),"Nincs kép és adat",IF(J16=0,"Nincs kép","Nincs adat"))) | N16: Nem | O16: – | P16: Nem kerestük – nincs ismert weboldal vagy katalógus | R16: https://website-9ib.pages.dev/termek/052900-muanyag-zartakaro/ | S16: 052900-muanyag-zartakaro
A17: Allco | B17: "h" szegő 25 mm | E17: 222139/n | F17: 2139 | G17: Platós és ponyvás oldalfal profilok és szegők | H17: Szegő profilok | I17: Quadris Excel | J17: 0 | K17: 0 | L17: nincs | M17: =IF(AND(J17>0,K17>0),"Rendben",IF(AND(J17=0,K17=0),"Nincs kép és adat",IF(J17=0,"Nincs kép","Nincs adat"))) | N17: Nem | O17: – | P17: Nem kerestük – nincs ismert weboldal vagy katalógus | R17: https://website-9ib.pages.dev/termek/222139-n-h-szego-25-mm/ | S17: 222139-n-h-szego-25-mm
A18: Allco | B18: "h" szegő 25 mm elox | E18: 222139 | F18: 1700038 | G18: Platós és ponyvás oldalfal profilok és szegők | H18: Szegő profilok | I18: Quadris Excel | J18: 0 | K18: 0 | L18: nincs | M18: =IF(AND(J18>0,K18>0),"Rendben",IF(AND(J18=0,K18=0),"Nincs kép és adat",IF(J18=0,"Nincs kép","Nincs adat"))) | N18: Nem | O18: – | P18: Nem kerestük – nincs ismert weboldal vagy katalógus | R18: https://website-9ib.pages.dev/termek/222139-h-szego-25-mm-elox/ | S18: 222139-h-szego-25-mm-elox
A19: Allco | B19: "u" 25 mm szegő profil | E19: 222137/n | F19: 2137 | G19: Platós és ponyvás oldalfal profilok és szegők | H19: Szegő profilok | I19: Quadris Excel | J19: 0 | K19: 0 | L19: nincs | M19: =IF(AND(J19>0,K19>0),"Rendben",IF(AND(J19=0,K19=0),"Nincs kép és adat",IF(J19=0,"Nincs kép","Nincs adat"))) | N19: Nem | O19: – | P19: Nem kerestük – nincs ismert weboldal vagy katalógus | R19: https://website-9ib.pages.dev/termek/222137-n-u-25-mm-szego-profil/ | S19: 222137-n-u-25-mm-szego-profil
A20: Allco | B20: "u" 25 mm szegő profil elox | E20: 222137 | F20: 2137 | G20: Platós és ponyvás oldalfal profilok és szegők | H20: Szegő profilok | I20: Quadris Excel | J20: 0 | K20: 0 | L20: nincs | M20: =IF(AND(J20>0,K20>0),"Rendben",IF(AND(J20=0,K20=0),"Nincs kép és adat",IF(J20=0,"Nincs kép","Nincs adat"))) | N20: Nem | O20: – | P20: Nem kerestük – nincs ismert weboldal vagy katalógus | R20: https://website-9ib.pages.dev/termek/222137-u-25-mm-szego-profil-elox/ | S20: 222137-u-25-mm-szego-profil-elox
A21: Allco | B21: Alsó tömítéses 200 mm elox profil | E21: 226115 | F21: VZPN1747 | G21: Platós és ponyvás oldalfal profilok és szegők | H21: 25 mm vastag oldalfal rendszerek | I21: Quadris Excel | J21: 0 | K21: 0 | L21: nincs | M21: =IF(AND(J21>0,K21>0),"Rendben",IF(AND(J21=0,K21=0),"Nincs kép és adat",IF(J21=0,"Nincs kép","Nincs adat"))) | N21: Nem | O21: – | P21: Nem kerestük – nincs ismert weboldal vagy katalógus | R21: https://website-9ib.pages.dev/termek/226115-also-tomiteses-200-mm-elox-profil/ | S21: 226115-also-tomiteses-200-mm-elox-profil
A22: Allco | B22: Ponyvabeakasztó alu profil 70 mm elox | E22: 388005 | F22: T1.8005.1 | G22: Ponyvarendszer kiegészítők | H22: Ponyvafeszítő profilok és alkatrészei | I22: Quadris Excel | J22: 0 | K22: 0 | L22: nincs | M22: =IF(AND(J22>0,K22>0),"Rendben",IF(AND(J22=0,K22=0),"Nincs kép és adat",IF(J22=0,"Nincs kép","Nincs adat"))) | N22: Nem | O22: – | P22: Nem kerestük – nincs ismert weboldal vagy katalógus | R22: https://website-9ib.pages.dev/termek/388005-ponyvabeakaszto-alu-profil-70-mm-elox/ | S22: 388005-ponyvabeakaszto-alu-profil-70-mm-elox
A23: ALSAP | B23: AN "h" ajtószegő 30 mm elox | E23: 231309 | F23: 1309AN | G23: Zárt-dobozos és hűtős profilok | H23: Zárt-dobozos és hűtős profilok | I23: Quadris Excel | J23: 0 | K23: 0 | L23: nincs | M23: =IF(AND(J23>0,K23>0),"Rendben",IF(AND(J23=0,K23=0),"Nincs kép és adat",IF(J23=0,"Nincs kép","Nincs adat"))) | N23: Nem | O23: – | P23: Nem kerestük – nincs ismert weboldal vagy katalógus | R23: https://website-9ib.pages.dev/termek/231309-an-h-ajtoszego-30-mm-elox/ | S23: 231309-an-h-ajtoszego-30-mm-elox
A24: ALSAP | B24: AN Tömítéses ajtószegő 30 mm elox | E24: 231308 | F24: 1308AN | G24: Zárt-dobozos és hűtős profilok | H24: Zárt-dobozos és hűtős profilok | I24: Quadris Excel | J24: 0 | K24: 0 | L24: nincs | M24: =IF(AND(J24>0,K24>0),"Rendben",IF(AND(J24=0,K24=0),"Nincs kép és adat",IF(J24=0,"Nincs kép","Nincs adat"))) | N24: Nem | O24: – | P24: Nem kerestük – nincs ismert weboldal vagy katalógus | R24: https://website-9ib.pages.dev/termek/231308-an-tomiteses-ajtoszego-30-mm-elox/ | S24: 231308-an-tomiteses-ajtoszego-30-mm-elox
A25: ALSAP | B25: CS Tömítéses ajtószegő 25 mm elox | E25: 238066 | F25: 223132E | G25: Zárt-dobozos és hűtős profilok | H25: Zárt-dobozos és hűtős profilok | I25: Quadris Excel | J25: 0 | K25: 0 | L25: nincs | M25: =IF(AND(J25>0,K25>0),"Rendben",IF(AND(J25=0,K25=0),"Nincs kép és adat",IF(J25=0,"Nincs kép","Nincs adat"))) | N25: Nem | O25: – | P25: Nem kerestük – nincs ismert weboldal vagy katalógus | R25: https://website-9ib.pages.dev/termek/238066-cs-tomiteses-ajtoszego-25-mm-elox/ | S25: 238066-cs-tomiteses-ajtoszego-25-mm-elox
A26: ALSAP | B26: Tömítés a szegő profilhoz | E26: 238067 | F26: 220306 | G26: Zárt-dobozos és hűtős profilok | H26: Zárt-dobozos és hűtős profilok | I26: Quadris Excel | J26: 0 | K26: 0 | L26: nincs | M26: =IF(AND(J26>0,K26>0),"Rendben",IF(AND(J26=0,K26=0),"Nincs kép és adat",IF(J26=0,"Nincs kép","Nincs adat"))) | N26: Nem | O26: – | P26: Nem kerestük – nincs ismert weboldal vagy katalógus | R26: https://website-9ib.pages.dev/termek/238067-tomites-a-szego-profilhoz/ | S26: 238067-tomites-a-szego-profilhoz
A27: Alu-SV | B27: Alu rakonca Top-kuplung | E27: 351155 | G27: Acél és alu rakoncák és szegők | H27: Alumínium rakoncák | I27: Quadris Excel | J27: 0 | K27: 0 | L27: nincs | M27: =IF(AND(J27>0,K27>0),"Rendben",IF(AND(J27=0,K27=0),"Nincs kép és adat",IF(J27=0,"Nincs kép","Nincs adat"))) | N27: Igen | O27: alu-sv.com webáruház, keresés rendelési számra | P27: Nem találtuk: alu-sv.com webáruház, keresés rendelési számra | R27: https://website-9ib.pages.dev/termek/351155-alu-rakonca-top-kuplung/ | S27: 351155-alu-rakonca-top-kuplung
A28: Alu-SV | B28: Alu rakonca magasító elox | E28: 351142 | F28: 62K113542B | G28: Acél és alu rakoncák és szegők | H28: Alumínium rakoncák | I28: Quadris Excel | J28: 0 | K28: 0 | L28: nincs | M28: =IF(AND(J28>0,K28>0),"Rendben",IF(AND(J28=0,K28=0),"Nincs kép és adat",IF(J28=0,"Nincs kép","Nincs adat"))) | N28: Igen | O28: alu-sv.com webáruház, keresés rendelési számra | P28: Nem találtuk: alu-sv.com webáruház, keresés rendelési számra | R28: https://website-9ib.pages.dev/termek/351142-alu-rakonca-magasito-elox/ | S28: 351142-alu-rakonca-magasito-elox
A29: Alu-SV | B29: KG hátsó alu szegőprofil elox | E29: 357271 | F29: 110900 | G29: Acél és alu rakoncák és szegők | H29: Alumínium rakoncák | I29: Quadris Excel | J29: 0 | K29: 0 | L29: nincs | M29: =IF(AND(J29>0,K29>0),"Rendben",IF(AND(J29=0,K29=0),"Nincs kép és adat",IF(J29=0,"Nincs kép","Nincs adat"))) | N29: Igen | O29: alu-sv.com webáruház, keresés rendelési számra | P29: Nem találtuk: alu-sv.com webáruház, keresés rendelési számra | R29: https://website-9ib.pages.dev/termek/357271-kg-hatso-alu-szegoprofil-elox/ | S29: 357271-kg-hatso-alu-szegoprofil-elox
A30: Alu-SV | B30: KG oldalsó alu szegő profil elox | E30: 357270 | F30: 110827 | G30: Acél és alu rakoncák és szegők | H30: Alumínium rakoncák | I30: Quadris Excel | J30: 0 | K30: 0 | L30: nincs | M30: =IF(AND(J30>0,K30>0),"Rendben",IF(AND(J30=0,K30=0),"Nincs kép és adat",IF(J30=0,"Nincs kép","Nincs adat"))) | N30: Igen | O30: alu-sv.com webáruház, keresés rendelési számra | P30: Nem találtuk: alu-sv.com webáruház, keresés rendelési számra | R30: https://website-9ib.pages.dev/termek/357270-kg-oldalso-alu-szego-profil-elox/ | S30: 357270-kg-oldalso-alu-szego-profil-elox
A31: Alu-SV | B31: Dupla görgős gumiütköző 222x115 | E31: 502502 | F31: 55322251 | G31: Dobozos felépítmény alkatrészek | H31: Gumiütközők | I31: Quadris Excel | J31: 0 | K31: 0 | L31: nincs | M31: =IF(AND(J31>0,K31>0),"Rendben",IF(AND(J31=0,K31=0),"Nincs kép és adat",IF(J31=0,"Nincs kép","Nincs adat"))) | N31: Igen | O31: alu-sv.com webáruház, keresés rendelési számra | P31: Nem találtuk: alu-sv.com webáruház, keresés rendelési számra | R31: https://website-9ib.pages.dev/termek/502502-dupla-gorgos-gumiutkozo-222x115/ | S31: 502502-dupla-gorgos-gumiutkozo-222x115
A32: Alu-SV | B32: Szimpla görgős gumiütköző/D100/118 | E32: 502501 | F32: 55322252 | G32: Dobozos felépítmény alkatrészek | H32: Gumiütközők | I32: Quadris Excel | J32: 0 | K32: 0 | L32: nincs | M32: =IF(AND(J32>0,K32>0),"Rendben",IF(AND(J32=0,K32=0),"Nincs kép és adat",IF(J32=0,"Nincs kép","Nincs adat"))) | N32: Igen | O32: alu-sv.com webáruház, keresés rendelési számra | P32: Nem találtuk: alu-sv.com webáruház, keresés rendelési számra | R32: https://website-9ib.pages.dev/termek/502501-szimpla-gorgos-gumiutkozo-d100-118/ | S32: 502501-szimpla-gorgos-gumiutkozo-d100-118
A33: Alu-SV | B33: Öntött sarokelem | E33: 103654 | G33: Dobozos felépítmény alkatrészek | H33: Egyéb dobozos felépítmény tartozékok | I33: Quadris Excel | J33: 0 | K33: 0 | L33: nincs | M33: =IF(AND(J33>0,K33>0),"Rendben",IF(AND(J33=0,K33=0),"Nincs kép és adat",IF(J33=0,"Nincs kép","Nincs adat"))) | N33: Igen | O33: alu-sv.com webáruház, keresés rendelési számra | P33: Nem találtuk: alu-sv.com webáruház, keresés rendelési számra | R33: https://website-9ib.pages.dev/termek/103654-ontott-sarokelem/ | S33: 103654-ontott-sarokelem
A34: Alu-SV | B34: MAX-os első elox oszlop 3000 mm | E34: 66177147 | F34: 66OP177147 | G34: Elhúzható rolóponyvás rendszer | H34: Alumínium sarok oszlopok | I34: Quadris Excel | J34: 0 | K34: 0 | L34: nincs | M34: =IF(AND(J34>0,K34>0),"Rendben",IF(AND(J34=0,K34=0),"Nincs kép és adat",IF(J34=0,"Nincs kép","Nincs adat"))) | N34: Igen | O34: alu-sv.com webáruház, keresés rendelési számra | P34: Nem találtuk: alu-sv.com webáruház, keresés rendelési számra | R34: https://website-9ib.pages.dev/termek/66177147-max-os-elso-elox-oszlop-3000-mm/ | S34: 66177147-max-os-elso-elox-oszlop-3000-mm
A35: Alu-SV | B35: MAX-os első elox oszlop 3150 mm | E35: 66177137 | F35: 66OP177137 | G35: Elhúzható rolóponyvás rendszer | H35: Alumínium sarok oszlopok | I35: Quadris Excel | J35: 0 | K35: 0 | L35: nincs | M35: =IF(AND(J35>0,K35>0),"Rendben",IF(AND(J35=0,K35=0),"Nincs kép és adat",IF(J35=0,"Nincs kép","Nincs adat"))) | N35: Igen | O35: alu-sv.com webáruház, keresés rendelési számra | P35: Nem találtuk: alu-sv.com webáruház, keresés rendelési számra | R35: https://website-9ib.pages.dev/termek/66177137-max-os-elso-elox-oszlop-3150-mm/ | S35: 66177137-max-os-elso-elox-oszlop-3150-mm
A36: Alu-SV | B36: MAX-os első elox oszlop 3300 mm | E36: 66177300 | F36: 66OP177127 | G36: Elhúzható rolóponyvás rendszer | H36: Alumínium sarok oszlopok | I36: Quadris Excel | J36: 0 | K36: 0 | L36: nincs | M36: =IF(AND(J36>0,K36>0),"Rendben",IF(AND(J36=0,K36=0),"Nincs kép és adat",IF(J36=0,"Nincs kép","Nincs adat"))) | N36: Igen | O36: alu-sv.com webáruház, keresés rendelési számra | P36: Nem találtuk: alu-sv.com webáruház, keresés rendelési számra | R36: https://website-9ib.pages.dev/termek/66177300-max-os-elso-elox-oszlop-3300-mm/ | S36: 66177300-max-os-elso-elox-oszlop-3300-mm
A37: Alu-SV | B37: MAX-os hátsó elox oszlop 3000 mm | E37: 6635245 | F37: 66OZ035245 | G37: Elhúzható rolóponyvás rendszer | H37: Alumínium sarok oszlopok | I37: Quadris Excel | J37: 0 | K37: 0 | L37: nincs | M37: =IF(AND(J37>0,K37>0),"Rendben",IF(AND(J37=0,K37=0),"Nincs kép és adat",IF(J37=0,"Nincs kép","Nincs adat"))) | N37: Igen | O37: alu-sv.com webáruház, keresés rendelési számra | P37: Nem találtuk: alu-sv.com webáruház, keresés rendelési számra | R37: https://website-9ib.pages.dev/termek/6635245-max-os-hatso-elox-oszlop-3000-mm/ | S37: 6635245-max-os-hatso-elox-oszlop-3000-mm
A38: Alu-SV | B38: MAX-os hátsó elox oszlop 3300 mm | E38: 6635300 | F38: 66OZ035265 | G38: Elhúzható rolóponyvás rendszer | H38: Alumínium sarok oszlopok | I38: Quadris Excel | J38: 0 | K38: 0 | L38: nincs | M38: =IF(AND(J38>0,K38>0),"Rendben",IF(AND(J38=0,K38=0),"Nincs kép és adat",IF(J38=0,"Nincs kép","Nincs adat"))) | N38: Igen | O38: alu-sv.com webáruház, keresés rendelési számra | P38: Nem találtuk: alu-sv.com webáruház, keresés rendelési számra | R38: https://website-9ib.pages.dev/termek/6635300-max-os-hatso-elox-oszlop-3300-mm/ | S38: 6635300-max-os-hatso-elox-oszlop-3300-mm
A39: Alu-SV | B39: MINI első FLAT alu oszlop elox | E39: 6613576 | F39: 6612013576 | G39: Elhúzható rolóponyvás rendszer | H39: Alumínium sarok oszlopok | I39: Quadris Excel | J39: 0 | K39: 0 | L39: nincs | M39: =IF(AND(J39>0,K39>0),"Rendben",IF(AND(J39=0,K39=0),"Nincs kép és adat",IF(J39=0,"Nincs kép","Nincs adat"))) | N39: Igen | O39: alu-sv.com webáruház, keresés rendelési számra | P39: Nem találtuk: alu-sv.com webáruház, keresés rendelési számra | R39: https://website-9ib.pages.dev/termek/6613576-mini-elso-flat-alu-oszlop-elox/ | S39: 6613576-mini-elso-flat-alu-oszlop-elox
A40: Alu-SV | B40: 3515P23 Alumínium zár ellendarab UNI elox | F40: 2ZSB3 | G40: Platós alkatrészek és kiegészítők | H40: Z-Zárak | I40: Quadris Excel | J40: 0 | K40: 0 | L40: nincs | M40: =IF(AND(J40>0,K40>0),"Rendben",IF(AND(J40=0,K40=0),"Nincs kép és adat",IF(J40=0,"Nincs kép","Nincs adat"))) | N40: Igen | O40: alu-sv.com webáruház, keresés rendelési számra | P40: Nem találtuk: alu-sv.com webáruház, keresés rendelési számra | R40: https://website-9ib.pages.dev/termek/3515p23-aluminium-zar-ellendarab-uni-elox/ | S40: 3515p23-aluminium-zar-ellendarab-uni-elox
...
